Workbook
Name Slicer_Representative: #N/A

Sheet Raw Data
B1: Call Centre Data
B3: Call number | C3: Customer ID | D3: Duration | E3: Representative | F3: Date of Call | G3: Purchase Amount | H3: Satisfaction Rating | I3: FY | J3: Day of week | K3: Duration Bucket | L3: Rating rounded | Q3: Customer ID | R3: Gedner | S3: Age | T3: City
B4: Call_7271 | C4: C0003 | D4: 116 | E4: R05 | F4: 44927 | G4: 128 | H4: 4.9 | I4: =IF(MONTH(calls[[#This Row],[Date of Call]])<=6, YEAR(calls[[#This Row],[Date of Call]]), YEAR(calls[[#This Row],[Date of Call]])+1) -> 2023 | J4: =TEXT(calls[[#This Row],[Date of Call]],"DDDD") -> Sunday | K4: {=_xlfn.IFS(calls[[#This Row],[Duration]]<=10,"Under 10 mins", calls[[#This Row],[Duration]]<=30, "10 to 30 mins", calls[[#This Row],[Duration]]<=60, "30 to 60 mins", calls[[#This Row],[Duration]]<=120, "1 to 2 hours", TRUE, "More than 2 hours")} -> 1 to 2 hours | L4: =ROUND(calls[[#This Row],[Satisfaction Rating]],0) -> 5 | Q4: C0001 | R4: Male | S4: 41 | T4: Columbus
B5: Call_7272 | C5: C0004 | D5: 119 | E5: R05 | F5: 44927 | G5: 135 | H5: 2.9 | I5: =IF(MONTH(calls[[#This Row],[Date of Call]])<=6, YEAR(calls[[#This Row],[Date of Call]]), YEAR(calls[[#This Row],[Date of Call]])+1) -> 2023 | J5: =TEXT(calls[[#This Row],[Date of Call]],"DDDD") -> Sunday | K5: {=_xlfn.IFS(calls[[#This Row],[Duration]]<=10,"Under 10 mins", calls[[#This Row],[Duration]]<=30, "10 to 30 mins", calls[[#This Row],[Duration]]<=60, "30 to 60 mins", calls[[#This Row],[Duration]]<=120, "1 to 2 hours", TRUE, "More than 2 hours")} -> 1 to 2 hours | L5: =ROUND(calls[[#This Row],[Satisfaction Rating]],0) -> 3 | Q5: C0002 | R5: Male | S5: 31 | T5: Cleveland
B6: Call_7273 | C6: C0005 | D6: 68 | E6: R02 | F6: 44927 | G6: 66 | H6: 4.7 | I6: =IF(MONTH(calls[[#This Row],[Date of Call]])<=6, YEAR(calls[[#This Row],[Date of Call]]), YEAR(calls[[#This Row],[Date of Call]])+1) -> 2023 | J6: =TEXT(calls[[#This Row],[Date of Call]],"DDDD") -> Sunday | K6: {=_xlfn.IFS(calls[[#This Row],[Duration]]<=10,"Under 10 mins", calls[[#This Row],[Duration]]<=30, "10 to 30 mins", calls[[#This Row],[Duration]]<=60, "30 to 60 mins", calls[[#This Row],[Duration]]<=120, "1 to 2 hours", TRUE, "More than 2 hours")} -> 1 to 2 hours | L6: =ROUND(calls[[#This Row],[Satisfaction Rating]],0) -> 5 | Q6: C0003 | R6: Male | S6: 26 | T6: Cincinnati
B7: Call_7274 | C7: C0014 | D7: 119 | E7: R02 | F7: 44927 | G7: 22 | H7: 2.9 | I7: =IF(MONTH(calls[[#This Row],[Date of Call]])<=6, YEAR(calls[[#This Row],[Date of Call]]), YEAR(calls[[#This Row],[Date of Call]])+1) -> 2023 | J7: =TEXT(calls[[#This Row],[Date of Call]],"DDDD") -> Sunday | K7: {=_xlfn.IFS(calls[[#This Row],[Duration]]<=10,"Under 10 mins", calls[[#This Row],[Duration]]<=30, "10 to 30 mins", calls[[#This Row],[Duration]]<=60, "30 to 60 mins", calls[[#This Row],[Duration]]<=120, "1 to 2 hours", TRUE, "More than 2 hours")} -> 1 to 2 hours | L7: =ROUND(calls[[#This Row],[Satisfaction Rating]],0) -> 3 | Q7: C0004 | R7: Male | S7: 36 | T7: Cincinnati
B8: Call_7275 | C8: C0011 | D8: 128 | E8: R01 | F8: 44928 | G8: 31 | H8: 2.8 | I8: =IF(MONTH(calls[[#This Row],[Date of Call]])<=6, YEAR(calls[[#This Row],[Date of Call]]), YEAR(calls[[#This Row],[Date of Call]])+1) -> 2023 | J8: =TEXT(calls[[#This Row],[Date of Call]],"DDDD") -> Monday | K8: {=_xlfn.IFS(calls[[#This Row],[Duration]]<=10,"Under 10 mins", calls[[#This Row],[Duration]]<=30, "10 to 30 mins", calls[[#This Row],[Duration]]<=60, "30 to 60 mins", calls[[#This Row],[Duration]]<=120, "1 to 2 hours", TRUE, "More than 2 hours")} -> More than 2 hours | L8: =ROUND(calls[[#This Row],[Satisfaction Rating]],0) -> 3 | Q8: C0005 | R8: Male | S8: 37 | T8: Columbus
B9: Call_7276 | C9: C0011 | D9: 49 | E9: R02 | F9: 44929 | G9: 135 | H9: 4.8 | I9: =IF(MONTH(calls[[#This Row],[Date of Call]])<=6, YEAR(calls[[#This Row],[Date of Call]]), YEAR(calls[[#This Row],[Date of Call]])+1) -> 2023 | J9: =TEXT(calls[[#This Row],[Date of Call]],"DDDD") -> Tuesday | K9: {=_xlfn.IFS(calls[[#This Row],[Duration]]<=10,"Under 10 mins", calls[[#This Row],[Duration]]<=30, "10 to 30 mins", calls[[#This Row],[Duration]]<=60, "30 to 60 mins", calls[[#This Row],[Duration]]<=120, "1 to 2 hours", TRUE, "More than 2 hours")} -> 30 to 60 mins | L9: =ROUND(calls[[#This Row],[Satisfaction Rating]],0) -> 5 | Q9: C0006 | R9: Male | S9: 23 | T9: Columbus
B10: Call_7277 | C10: C0007 | D10: 84 | E10: R05 | F10: 44929 | G10: 60 | H10: 4.7 | I10: =IF(MONTH(calls[[#This Row],[Date of Call]])<=6, YEAR(calls[[#This Row],[Date of Call]]), YEAR(calls[[#This Row],[Date of Call]])+1) -> 2023 | J10: =TEXT(calls[[#This Row],[Date of Call]],"DDDD") -> Tuesday | K10: {=_xlfn.IFS(calls[[#This Row],[Duration]]<=10,"Under 10 mins", calls[[#This Row],[Duration]]<=30, "10 to 30 mins", calls[[#This Row],[Duration]]<=60, "30 to 60 mins", calls[[#This Row],[Duration]]<=120, "1 to 2 hours", TRUE, "More than 2 hours")} -> 1 to 2 hours | L10: =ROUND(calls[[#This Row],[Satisfaction Rating]],0) -> 5 | Q10: C0007 | R10: Female | S10: 22 | T10: Cleveland
B11: Call_7278 | C11: C0003 | D11: 103 | E11: R04 | F11: 44929 | G11: 148 | H11: 4.4 | I11: =IF(MONTH(calls[[#This Row],[Date of Call]])<=6, YEAR(calls[[#This Row],[Date of Call]]), YEAR(calls[[#This Row],[Date of Call]])+1) -> 2023 | J11: =TEXT(calls[[#This Row],[Date of Call]],"DDDD") -> Tuesday | K11: {=_xlfn.IFS(calls[[#This Row],[Duration]]<=10,"Under 10 mins", calls[[#This Row],[Duration]]<=30, "10 to 30 mins", calls[[#This Row],[Duration]]<=60, "30 to 60 mins", calls[[#This Row],[Duration]]<=120, "1 to 2 hours", TRUE, "More than 2 hours")} -> 1 to 2 hours | L11: =ROUND(calls[[#This Row],[Satisfaction Rating]],0) -> 4 | Q11: C0008 | R11: Female | S11: 42 | T11: Cleveland
B12: Call_7279 | C12: C0005 | D12: 31 | E12: R02 | F12: 44929 | G12: 135 | H12: 3.6 | I12: =IF(MONTH(calls[[#This Row],[Date of Call]])<=6, YEAR(calls[[#This Row],[Date of Call]]), YEAR(calls[[#This Row],[Date of Call]])+1) -> 2023 | J12: =TEXT(calls[[#This Row],[Date of Call]],"DDDD") -> Tuesday | K12: {=_xlfn.IFS(calls[[#This Row],[Duration]]<=10,"Under 10 mins", calls[[#This Row],[Duration]]<=30, "10 to 30 mins", calls[[#This Row],[Duration]]<=60, "30 to 60 mins", calls[[#This Row],[Duration]]<=120, "1 to 2 hours", TRUE, "More than 2 hours")} -> 30 to 60 mins | L12: =ROUND(calls[[#This Row],[Satisfaction Rating]],0) -> 4 | Q12: C0009 | R12: Female | S12: 25 | T12: Columbus
B13: Call_7280 | C13: C0010 | D13: 44 | E13: R03 | F13: 44929 | G13: 105 | H13: 2.9 | I13: =IF(MONTH(calls[[#This Row],[Date of Call]])<=6, YEAR(calls[[#This Row],[Date of Call]]), YEAR(calls[[#This Row],[Date of Call]])+1) -> 2023 | J13: =TEXT(calls[[#This Row],[Date of Call]],"DDDD") -> Tuesday | K13: {=_xlfn.IFS(calls[[#This Row],[Duration]]<=10,"Under 10 mins", calls[[#This Row],[Duration]]<=30, "10 to 30 mins", calls[[#This Row],[Duration]]<=60, "30 to 60 mins", calls[[#This Row],[Duration]]<=120, "1 to 2 hours", TRUE, "More than 2 hours")} -> 30 to 60 mins | L13: =ROUND(calls[[#This Row],[Satisfaction Rating]],0) -> 3 | Q13: C0010 | R13: Female | S13: 30 | T13: Cleveland
B14: Call_7281 | C14: C0011 | D14: 102 | E14: R02 | F14: 44929 | G14: 69 | H14: 4.9 | I14: =IF(MONTH(calls[[#This Row],[Date of Call]])<=6, YEAR(calls[[#This Row],[Date of Call]]), YEAR(calls[[#This Row],[Date of Call]])+1) -> 2023 | J14: =TEXT(calls[[#This Row],[Date of Call]],"DDDD") -> Tuesday | K14: {=_xlfn.IFS(calls[[#This Row],[Duration]]<=10,"Under 10 mins", calls[[#This Row],[Duration]]<=30, "10 to 30 mins", calls[[#This Row],[Duration]]<=60, "30 to 60 mins", calls[[#This Row],[Duration]]<=120, "1 to 2 hours", TRUE, "More than 2 hours")} -> 1 to 2 hours | L14: =ROUND(calls[[#This Row],[Satisfaction Rating]],0) -> 5 | Q14: C0011 | R14: Female | S14: 30 | T14: Cincinnati
B15: Call_7282 | C15: C0013 | D15: 135 | E15: R05 | F15: 44929 | G15: 46 | H15: 3.4 | I15: =IF(MONTH(calls[[#This Row],[Date of Call]])<=6, YEAR(calls[[#This Row],[Date of Call]]), YEAR(calls[[#This Row],[Date of Call]])+1) -> 2023 | J15: =TEXT(calls[[#This Row],[Date of Call]],"DDDD") -> Tuesday | K15: {=_xlfn.IFS(calls[[#This Row],[Duration]]<=10,"Under 10 mins", calls[[#This Row],[Duration]]<=30, "10 to 30 mins", calls[[#This Row],[Duration]]<=60, "30 to 60 mins", calls[[#This Row],[Duration]]<=120, "1 to 2 hours", TRUE, "More than 2 hours")} -> More than 2 hours | L15: =ROUND(calls[[#This Row],[Satisfaction Rating]],0) -> 3 | Q15: C0012 | R15: Female | S15: 28 | T15: Cincinnati
... B18: Call_7285 | C18: C0013 | D18: 48 | E18: R01 | F18: 44930 | G18: 68 | H18: 4.9 | I18: =IF(MONTH(calls[[#This Row],[Date of Call]])<=6, YEAR(calls[[#This Row],[Date of Call]]), YEAR(calls[[#This Row],[Date of Call]])+1) -> 2023 | J18: =TEXT(calls[[#This Row],[Date of Call]],"DDDD") -> Wednesday | K18: {=_xlfn.IFS(calls[[#This Row],[Duration]]<=10,"Under 10 mins", calls[[#This Row],[Duration]]<=30, "10 to 30 mins", calls[[#This Row],[Duration]]<=60, "30 to 60 mins", calls[[#This Row],[Duration]]<=120, "1 to 2 hours", TRUE, "More than 2 hours")} -> 30 to 60 mins | L18: =ROUND(calls[[#This Row],[Satisfaction Rating]],0) -> 5 | Q18: C0015 | R18: Female | S18: 43 | T18: Cleveland
B19: Call_7286 | C19: C0010 | D19: 176 | E19: R05 | F19: 44931 | G19: 24 | H19: 4.8 | I19: =IF(MONTH(calls[[#This Row],[Date of Call]])<=6, YEAR(calls[[#This Row],[Date of Call]]), YEAR(calls[[#This Row],[Date of Call]])+1) -> 2023 | J19: =TEXT(calls[[#This Row],[Date of Call]],"DDDD") -> Thursday | K19: {=_xlfn.IFS(calls[[#This Row],[Duration]]<=10,"Under 10 mins", calls[[#This Row],[Duration]]<=30, "10 to 30 mins", calls[[#This Row],[Duration]]<=60, "30 to 60 mins", calls[[#This Row],[Duration]]<=120, "1 to 2 hours", TRUE, "More than 2 hours")} -> More than 2 hours | L19: =ROUND(calls[[#This Row],[Satisfaction Rating]],0) -> 5
B20: Call_7287 | C20: C0010 | D20: 99 | E20: R01 | F20: 44931 | G20: 195 | H20: 3.9 | I20: =IF(MONTH(calls[[#This Row],[Date of Call]])<=6, YEAR(calls[[#This Row],[Date of Call]]), YEAR(calls[[#This Row],[Date of Call]])+1) -> 2023 | J20: =TEXT(calls[[#This Row],[Date of Call]],"DDDD") -> Thursday | K20: {=_xlfn.IFS(calls[[#This Row],[Duration]]<=10,"Under 10 mins", calls[[#This Row],[Duration]]<=30, "10 to 30 mins", calls[[#This Row],[Duration]]<=60, "30 to 60 mins", calls[[#This Row],[Duration]]<=120, "1 to 2 hours", TRUE, "More than 2 hours")} -> 1 to 2 hours | L20: =ROUND(calls[[#This Row],[Satisfaction Rating]],0) -> 4
B21: Call_7288 | C21: C0009 | D21: 28 | E21: R03 | F21: 44931 | G21: 28 | H21: 3.8 | I21: =IF(MONTH(calls[[#This Row],[Date of Call]])<=6, YEAR(calls[[#This Row],[Date of Call]]), YEAR(calls[[#This Row],[Date of Call]])+1) -> 2023 | J21: =TEXT(calls[[#This Row],[Date of Call]],"DDDD") -> Thursday | K21: {=_xlfn.IFS(calls[[#This Row],[Duration]]<=10,"Under 10 mins", calls[[#This Row],[Duration]]<=30, "10 to 30 mins", calls[[#This Row],[Duration]]<=60, "30 to 60 mins", calls[[#This Row],[Duration]]<=120, "1 to 2 hours", TRUE, "More than 2 hours")} -> 10 to 30 mins | L21: =ROUND(calls[[#This Row],[Satisfaction Rating]],0) -> 4
B22: Call_7289 | C22: C0007 | D22: 54 | E22: R02 | F22: 44931 | G22: 170 | H22: 4.3 | I22: =IF(MONTH(calls[[#This Row],[Date of Call]])<=6, YEAR(calls[[#This Row],[Date of Call]]), YEAR(calls[[#This Row],[Date of Call]])+1) -> 2023 | J22: =TEXT(calls[[#This Row],[Date of Call]],"DDDD") -> Thursday | K22: {=_xlfn.IFS(calls[[#This Row],[Duration]]<=10,"Under 10 mins", calls[[#This Row],[Duration]]<=30, "10 to 30 mins", calls[[#This Row],[Duration]]<=60, "30 to 60 mins", calls[[#This Row],[Duration]]<=120, "1 to 2 hours", TRUE, "More than 2 hours")} -> 30 to 60 mins | L22: =ROUND(calls[[#This Row],[Satisfaction Rating]],0) -> 4
B23: Call_7290 | C23: C0006 | D23: 48 | E23: R05 | F23: 44932 | G23: 30 | H23: 4.4 | I23: =IF(MONTH(calls[[#This Row],[Date of Call]])<=6, YEAR(calls[[#This Row],[Date of Call]]), YEAR(calls[[#This Row],[Date of Call]])+1) -> 2023 | J23: =TEXT(calls[[#This Row],[Date of Call]],"DDDD") -> Friday | K23: {=_xlfn.IFS(calls[[#This Row],[Duration]]<=10,"Under 10 mins", calls[[#This Row],[Duration]]<=30, "10 to 30 mins", calls[[#This Row],[Duration]]<=60, "30 to 60 mins", calls[[#This Row],[Duration]]<=120, "1 to 2 hours", TRUE, "More than 2 hours")} -> 30 to 60 mins | L23: =ROUND(calls[[#This Row],[Satisfaction Rating]],0) -> 4
B24: Call_7291 | C24: C0004 | D24: 128 | E24: R05 | F24: 44932 | G24: 72 | H24: 5 | I24: =IF(MONTH(calls[[#This Row],[Date of Call]])<=6, YEAR(calls[[#This Row],[Date of Call]]), YEAR(calls[[#This Row],[Date of Call]])+1) -> 2023 | J24: =TEXT(calls[[#This Row],[Date of Call]],"DDDD") -> Friday | K24: {=_xlfn.IFS(calls[[#This Row],[Duration]]<=10,"Under 10 mins", calls[[#This Row],[Duration]]<=30, "10 to 30 mins", calls[[#This Row],[Duration]]<=60, "30 to 60 mins", calls[[#This Row],[Duration]]<=120, "1 to 2 hours", TRUE, "More than 2 hours")} -> More than 2 hours | L24: =ROUND(calls[[#This Row],[Satisfaction Rating]],0) -> 5
B25: Call_7292 | C25: C0004 | D25: 38 | E25: R04 | F25: 44933 | G25: 92 | H25: 4.9 | I25: =IF(MONTH(calls[[#This Row],[Date of Call]])<=6, YEAR(calls[[#This Row],[Date of Call]]), YEAR(calls[[#This Row],[Date of Call]])+1) -> 2023 | J25: =TEXT(calls[[#This Row],[Date of Call]],"DDDD") -> Saturday | K25: {=_xlfn.IFS(calls[[#This Row],[Duration]]<=10,"Under 10 mins", calls[[#This Row],[Duration]]<=30, "10 to 30 mins", calls[[#This Row],[Duration]]<=60, "30 to 60 mins", calls[[#This Row],[Duration]]<=120, "1 to 2 hours", TRUE, "More than 2 hours")} -> 30 to 60 mins | L25: =ROUND(calls[[#This Row],[Satisfaction Rating]],0) -> 5
B26: Call_7293 | C26: C0003 | D26: 67 | E26: R04 | F26: 44934 | G26: 165 | H26: 4.5 | I26: =IF(MONTH(calls[[#This Row],[Date of Call]])<=6, YEAR(calls[[#This Row],[Date of Call]]), YEAR(calls[[#This Row],[Date of Call]])+1) -> 2023 | J26: =TEXT(calls[[#This Row],[Date of Call]],"DDDD") -> Sunday | K26: {=_xlfn.IFS(calls[[#This Row],[Duration]]<=10,"Under 10 mins", calls[[#This Row],[Duration]]<=30, "10 to 30 mins", calls[[#This Row],[Duration]]<=60, "30 to 60 mins", calls[[#This Row],[Duration]]<=120, "1 to 2 hours", TRUE, "More than 2 hours")} -> 1 to 2 hours | L26: =ROUND(calls[[#This Row],[Satisfaction Rating]],0) -> 5
B27: Call_7294 | C27: C0015 | D27: 58 | E27: R02 | F27: 44934 | G27: 140 | H27: 2.1 | I27: =IF(MONTH(calls[[#This Row],[Date of Call]])<=6, YEAR(calls[[#This Row],[Date of Call]]), YEAR(calls[[#This Row],[Date of Call]])+1) -> 2023 | J27: =TEXT(calls[[#This Row],[Date of Call]],"DDDD") -> Sunday | K27: {=_xlfn.IFS(calls[[#This Row],[Duration]]<=10,"Under 10 mins", calls[[#This Row],[Duration]]<=30, "10 to 30 mins", calls[[#This Row],[Duration]]<=60, "30 to 60 mins", calls[[#This Row],[Duration]]<=120, "1 to 2 hours", TRUE, "More than 2 hours")} -> 30 to 60 mins | L27: =ROUND(calls[[#This Row],[Satisfaction Rating]],0) -> 2
B28: Call_7295 | C28: C0010 | D28: 54 | E28: R01 | F28: 44934 | G28: 111 | H28: 3.3 | I28: =IF(MONTH(calls[[#This Row],[Date of Call]])<=6, YEAR(calls[[#This Row],[Date of Call]]), YEAR(calls[[#This Row],[Date of Call]])+1) -> 2023 | J28: =TEXT(calls[[#This Row],[Date of Call]],"DDDD") -> Sunday | K28: {=_xlfn.IFS(calls[[#This Row],[Duration]]<=10,"Under 10 mins", calls[[#This Row],[Duration]]<=30, "10 to 30 mins", calls[[#This Row],[Duration]]<=60, "30 to 60 mins", calls[[#This Row],[Duration]]<=120, "1 to 2 hours", TRUE, "More than 2 hours")} -> 30 to 60 mins | L28: =ROUND(calls[[#This Row],[Satisfaction Rating]],0) -> 3
B29: Call_7296 | C29: C0012 | D29: 28 | E29: R05 | F29: 44935 | G29: 63 | H29: 4.1 | I29: =IF(MONTH(calls[[#This Row],[Date of Call]])<=6, YEAR(calls[[#This Row],[Date of Call]]), YEAR(calls[[#This Row],[Date of Call]])+1) -> 2023 | J29: =TEXT(calls[[#This Row],[Date of Call]],"DDDD") -> Monday | K29: {=_xlfn.IFS(calls[[#This Row],[Duration]]<=10,"Under 10 mins", calls[[#This Row],[Duration]]<=30, "10 to 30 mins", calls[[#This Row],[Duration]]<=60, "30 to 60 mins", calls[[#This Row],[Duration]]<=120, "1 to 2 hours", TRUE, "More than 2 hours")} -> 10 to 30 mins | L29: =ROUND(calls[[#This Row],[Satisfaction Rating]],0) -> 4
B30: Call_7297 | C30: C0002 | D30: 73 | E30: R05 | F30: 44935 | G30: 80 | H30: 4.2 | I30: =IF(MONTH(calls[[#This Row],[Date of Call]])<=6, YEAR(calls[[#This Row],[Date of Call]]), YEAR(calls[[#This Row],[Date of Call]])+1) -> 2023 | J30: =TEXT(calls[[#This Row],[Date of Call]],"DDDD") -> Monday | K30: {=_xlfn.IFS(calls[[#This Row],[Duration]]<=10,"Under 10 mins", calls[[#This Row],[Duration]]<=30, "10 to 30 mins", calls[[#This Row],[Duration]]<=60, "30 to 60 mins", calls[[#This Row],[Duration]]<=120, "1 to 2 hours", TRUE, "More than 2 hours")} -> 1 to 2 hours | L30: =ROUND(calls[[#This Row],[Satisfaction Rating]],0) -> 4
... B1003: Call_8270 | C1003: C0009 | D1003: 114 | E1003: R01 | F1003: 45291 | G1003: 40 | H1003: 3.9 | I1003: =IF(MONTH(calls[[#This Row],[Date of Call]])<=6, YEAR(calls[[#This Row],[Date of Call]]), YEAR(calls[[#This Row],[Date of Call]])+1) -> 2024 | J1003: =TEXT(calls[[#This Row],[Date of Call]],"DDDD") -> Sunday | K1003: {=_xlfn.IFS(calls[[#This Row],[Duration]]<=10,"Under 10 mins", calls[[#This Row],[Duration]]<=30, "10 to 30 mins", calls[[#This Row],[Duration]]<=60, "30 to 60 mins", calls[[#This Row],[Duration]]<=120, "1 to 2 hours", TRUE, "More than 2 hours")} -> 1 to 2 hours | L1003: =ROUND(calls[[#This Row],[Satisfaction Rating]],0) -> 4

Sheet Data Analyst
A3: Call Count | B3: Total Amount | C3: Total Durations | D3: Avg. Rating | E3: 5*Calls
A4: 1000 | B4: 96623 | C4: 89850 | D4: 3.8854 | E4: 307
A8: Call Count | B8: Total Amount | C8: Total Durations | D8: Avg. Rating | E8: 5*Calls
A9: 1000 | B9: 96623 | C9: 89850 | D9: 3.8854 | E9: 307
A15: Row Labels | B15: Call Count | C15: Call Count2
A16: Jan | B16: 79 | C16: 79
A17: Feb | B17: 66 | C17: 66
A18: Mar | B18: 155 | C18: 155
A19: Apr | B19: 136 | C19: 136
A20: May | B20: 83 | C20: 83
A21: Jun | B21: 67 | C21: 67
A22: Jul | B22: 64 | C22: 64
A23: Aug | B23: 50 | C23: 50
A24: Sep | B24: 76 | C24: 76
A25: Oct | B25: 114 | C25: 114
A26: Nov | B26: 57 | C26: 57
A27: Dec | B27: 53 | C27: 53
A28: Grand Total | B28: 1000 | C28: 1000
A32: Row Labels | B32: Call Count
A33: Sunday | B33: 146
A34: Saturday | B34: 161
A35: Friday | B35: 141
A36: Thursday | B36: 128
A37: Wednesday | B37: 153
A38: Tuesday | B38: 138
A39: Monday | B39: 133
A40: Grand Total | B40: 1000
K41: 40
I43: Selected rep | J43: =A59 -> R01
F44: For Graph
A45: Row Labels | B45: Call Count | C45: Total Amount | F45: Rep | G45: Call | H45: Amount | I45: Sel.calls | J45: Sel.Amt
A46: R01 | B46: 189 | C46: 18415 | F46: =A46 -> R01 | G46: =B46 -> 189 | H46: =C46 -> 18415 | I46: =IF(F46=$J$43,G46,NA()) -> 189 | J46: =IF(F46=$J$43,H46,NA()) -> 18415
A47: R02 | B47: 218 | C47: 20581 | F47: =A47 -> R02 | G47: =B47 -> 218 | H47: =C47 -> 20581 | I47: =IF(F47=$J$43,G47,NA()) -> #N/A | J47: =IF(F47=$J$43,H47,NA()) -> #N/A
A48: R03 | B48: 207 | C48: 20872 | F48: =A48 -> R03 | G48: =B48 -> 207 | H48: =C48 -> 20872 | I48: =IF(F48=$J$43,G48,NA()) -> #N/A | J48: =IF(F48=$J$43,H48,NA()) -> #N/A
A49: R04 | B49: 186 | C49: 16651 | F49: =A49 -> R04 | G49: =B49 -> 186 | H49: =C49 -> 16651 | I49: =IF(F49=$J$43,G49,NA()) -> #N/A | J49: =IF(F49=$J$43,H49,NA()) -> #N/A
A50: R05 | B50: 200 | C50: 20104 | F50: =A50 -> R05 | G50: =B50 -> 200 | H50: =C50 -> 20104 | I50: =IF(F50=$J$43,G50,NA()) -> #N/A | J50: =IF(F50=$J$43,H50,NA()) -> #N/A
A51: Grand Total | B51: 1000 | C51: 96623
B55: best Trick to Note
E57: Rep Summary
A58: Row Labels
...

Sheet Dashboard
M15: {='Data Analyst'!B86:F86} -> R01 | N15: R02 | O15: R03 | P15: R04 | Q15: R05 | R15: Total
L16: {=IF('Data Analyst'!A87:G104="", "",'Data Analyst'!A87:G104)} -> Cincinnati
L17: C0003 | M17: 891 | N17: 1332 | O17: 1282 | P17: 739 | Q17: 560 | R17: 4804
L18: C0004 | M18: 1991 | N18: 1886 | O18: 1206 | P18: 884 | Q18: 1722 | R18: 7689
L19: C0011 | M19: 1163 | N19: 1180 | O19: 1616 | P19: 1043 | Q19: 1747 | R19: 6749
L20: C0012 | M20: 1438 | N20: 1616 | O20: 866 | P20: 829 | Q20: 2070 | R20: 6819
L21: Cleveland
L22: C0002 | M22: 1233 | N22: 223 | O22: 1680 | P22: 990 | Q22: 1508 | R22: 5634
L23: C0007 | M23: 1598 | N23: 1907 | O23: 869 | P23: 1426 | Q23: 1416 | R23: 7216
L24: C0008 | M24: 900 | N24: 1016 | O24: 960 | P24: 940 | Q24: 1193 | R24: 5009
L25: C0010 | M25: 900 | N25: 1470 | O25: 1617 | P25: 1314 | Q25: 941 | R25: 6242
J26: ='Data Analyst'!I63 | L26: C0013 | M26: 1255 | N26: 516 | O26: 1874 | P26: 1863 | Q26: 1722 | R26: 7230
L27: C0015 | M27: 1138 | N27: 1898 | O27: 1482 | P27: 846 | Q27: 1154 | R27: 6518
L28: Columbus
J29: ='Data Analyst'!I60 | L29: C0001 | M29: 1655 | N29: 805 | O29: 2263 | P29: 987 | Q29: 1075 | R29: 6785
J30: ='Data Analyst'!I61 | L30: C0005 | M30: 1104 | N30: 2280 | O30: 1445 | P30: 1722 | Q30: 1196 | R30: 7747
J31: ='Data Analyst'!I62 | L31: C0006 | M31: 372 | N31: 1818 | O31: 1346 | P31: 1156 | Q31: 1484 | R31: 6176
L32: C0009 | M32: 1415 | N32: 1271 | O32: 1214 | P32: 1135 | Q32: 1566 | R32: 6601
L33: C0014 | M33: 1362 | N33: 1363 | O33: 1152 | P33: 777 | Q33: 750 | R33: 5404

Sheet Assets
E2: Rep ID | F2: Rep Image
E3: R01 | F3: #VALUE!
E4: R02 | F4: #VALUE!
E5: R03 | F5: #VALUE!
E6: R04 | F6: #VALUE!
E7: R05 | F7: #VALUE!

Sheet My insight
A1: Call Volume and Trends:
A3: The call trend graph shows fluctuations, with peaks in April and October. Identifying the reasons behind these peaks can help you plan and optimize resources during high-demand periods.
A5: Revenue Generation:
A7: The total revenue generated is $96,623. Some representatives (e.g., R02 and R05) generate higher amounts. Focusing on their strategies and training others can help increase overall revenue.
A9: Call Durations:
A11: The total call duration is 89,850 minutes. Analyzing the efficiency of calls and finding ways to reduce call times without compromising service quality can improve productivity.
A13: Average Ratings and Happy Callers:
A15: The average rating is 3.9, with 307 happy callers. Enhancing customer service to increase ratings and the number of happy callers can lead to better customer retention and satisfaction.
A17: Day of the Week Analysis:
A19: Saturday has the highest call volume (161), while Thursday has the lowest (128). Adjusting staffing levels based on this data can ensure adequate coverage during peak times.
A21: Gender Analysis:
A23: Cleveland has a higher number of male callers (326) compared to female callers (63). Understanding the demographics and preferences of callers in different cities can help tailor marketing and service strategies.
... A27: The detailed performance metrics for representatives across different clients can be leveraged. Identifying top performers and understanding their techniques can help in training and improving the performance of other representatives.

Sheet Tasks
A1: CALL CENTRE REPORT – 2023
A3: Tasks & Instructions Followed
A5: Data Preparation using Power Query:
A7: Cleaned and transformed both Calls Table and Customers Table
A9: Merged datasets to associate customer demographic info with call details
A11: Dashboard Tasks Completed:
A13: Built key performance indicators (KPIs): total calls, amount, duration, average rating, happy callers
A15: Plotted call trends across months
A17: Created visual breakdowns:
A21: Calls by representative
A23: Purchase amount by representative
A25: Gender and city-wise distribution
... A37: Ensured the dashboard is self-explanatory and filter-friendly
